Not Found: /
Not Found: /
Not Found: /
Not Found: /123123
Not Found: /
Not Found: /
Not Found: /
Not Found: /
Internal Server Error: /rooms/create
Traceback (most recent call last):
  File "/Library/Python/2.7/site-packages/django/core/handlers/base.py", line 114, in get_response
    response = wrapped_callback(request, *callback_args, **callback_kwargs)
  File "/Library/Python/2.7/site-packages/django/views/decorators/csrf.py", line 57, in wrapped_view
    return view_func(*args, **kwargs)
  File "/Users/Uijune/Documents/tyrant_server/controller/roomcontroller.py", line 42, in create_room
    username = request.POST['username']
  File "/Library/Python/2.7/site-packages/django/utils/datastructures.py", line 301, in __getitem__
    raise MultiValueDictKeyError(repr(key))
MultiValueDictKeyError: "'username'"
Internal Server Error: /rooms/create
Traceback (most recent call last):
  File "/Library/Python/2.7/site-packages/django/core/handlers/base.py", line 90, in get_response
    response = middleware_method(request)
  File "/Library/Python/2.7/site-packages/django/middleware/common.py", line 71, in process_request
    if (not urlresolvers.is_valid_path(request.path_info, urlconf) and
  File "/Library/Python/2.7/site-packages/django/core/urlresolvers.py", line 573, in is_valid_path
    resolve(path, urlconf)
  File "/Library/Python/2.7/site-packages/django/core/urlresolvers.py", line 453, in resolve
    return get_resolver(urlconf).resolve(path)
  File "/Library/Python/2.7/site-packages/django/core/urlresolvers.py", line 320, in resolve
    sub_match = pattern.resolve(new_path)
  File "/Library/Python/2.7/site-packages/django/core/urlresolvers.py", line 222, in resolve
    return ResolverMatch(self.callback, args, kwargs, self.name)
  File "/Library/Python/2.7/site-packages/django/core/urlresolvers.py", line 229, in callback
    self._callback = get_callable(self._callback_str)
  File "/Library/Python/2.7/site-packages/django/utils/functional.py", line 32, in wrapper
    result = func(*args)
  File "/Library/Python/2.7/site-packages/django/core/urlresolvers.py", line 96, in get_callable
    mod = import_module(mod_name)
  File "/Library/Python/2.7/site-packages/django/utils/importlib.py", line 40, in import_module
    __import__(name)
  File "/Users/Uijune/Documents/tyrant_server/controller/roomcontroller.py", line 95
    if len(room) != 1
                    ^
SyntaxError: invalid syntax
Internal Server Error: /rooms/create
Traceback (most recent call last):
  File "/Library/Python/2.7/site-packages/django/core/handlers/base.py", line 90, in get_response
    response = middleware_method(request)
  File "/Library/Python/2.7/site-packages/django/middleware/common.py", line 71, in process_request
    if (not urlresolvers.is_valid_path(request.path_info, urlconf) and
  File "/Library/Python/2.7/site-packages/django/core/urlresolvers.py", line 573, in is_valid_path
    resolve(path, urlconf)
  File "/Library/Python/2.7/site-packages/django/core/urlresolvers.py", line 453, in resolve
    return get_resolver(urlconf).resolve(path)
  File "/Library/Python/2.7/site-packages/django/core/urlresolvers.py", line 320, in resolve
    sub_match = pattern.resolve(new_path)
  File "/Library/Python/2.7/site-packages/django/core/urlresolvers.py", line 222, in resolve
    return ResolverMatch(self.callback, args, kwargs, self.name)
  File "/Library/Python/2.7/site-packages/django/core/urlresolvers.py", line 229, in callback
    self._callback = get_callable(self._callback_str)
  File "/Library/Python/2.7/site-packages/django/utils/functional.py", line 32, in wrapper
    result = func(*args)
  File "/Library/Python/2.7/site-packages/django/core/urlresolvers.py", line 96, in get_callable
    mod = import_module(mod_name)
  File "/Library/Python/2.7/site-packages/django/utils/importlib.py", line 40, in import_module
    __import__(name)
  File "/Users/Uijune/Documents/tyrant_server/controller/roomcontroller.py", line 95
    if len(room) != 1
                    ^
SyntaxError: invalid syntax
Internal Server Error: /rooms/leave
Traceback (most recent call last):
  File "/Library/Python/2.7/site-packages/django/core/handlers/base.py", line 90, in get_response
    response = middleware_method(request)
  File "/Library/Python/2.7/site-packages/django/middleware/common.py", line 71, in process_request
    if (not urlresolvers.is_valid_path(request.path_info, urlconf) and
  File "/Library/Python/2.7/site-packages/django/core/urlresolvers.py", line 573, in is_valid_path
    resolve(path, urlconf)
  File "/Library/Python/2.7/site-packages/django/core/urlresolvers.py", line 453, in resolve
    return get_resolver(urlconf).resolve(path)
  File "/Library/Python/2.7/site-packages/django/core/urlresolvers.py", line 320, in resolve
    sub_match = pattern.resolve(new_path)
  File "/Library/Python/2.7/site-packages/django/core/urlresolvers.py", line 222, in resolve
    return ResolverMatch(self.callback, args, kwargs, self.name)
  File "/Library/Python/2.7/site-packages/django/core/urlresolvers.py", line 229, in callback
    self._callback = get_callable(self._callback_str)
  File "/Library/Python/2.7/site-packages/django/utils/functional.py", line 32, in wrapper
    result = func(*args)
  File "/Library/Python/2.7/site-packages/django/core/urlresolvers.py", line 96, in get_callable
    mod = import_module(mod_name)
  File "/Library/Python/2.7/site-packages/django/utils/importlib.py", line 40, in import_module
    __import__(name)
  File "/Users/Uijune/Documents/tyrant_server/controller/roomcontroller.py", line 95
    if len(room) != 1
                    ^
SyntaxError: invalid syntax
Internal Server Error: /rooms/leave
Traceback (most recent call last):
  File "/Library/Python/2.7/site-packages/django/core/handlers/base.py", line 114, in get_response
    response = wrapped_callback(request, *callback_args, **callback_kwargs)
  File "/Library/Python/2.7/site-packages/django/views/decorators/csrf.py", line 57, in wrapped_view
    return view_func(*args, **kwargs)
  File "/Users/Uijune/Documents/tyrant_server/controller/roomcontroller.py", line 85, in leave_room
    username = request.POST['username']
  File "/Library/Python/2.7/site-packages/django/utils/datastructures.py", line 301, in __getitem__
    raise MultiValueDictKeyError(repr(key))
MultiValueDictKeyError: "'username'"
Internal Server Error: /rooms/leave
Traceback (most recent call last):
  File "/Library/Python/2.7/site-packages/django/core/handlers/base.py", line 114, in get_response
    response = wrapped_callback(request, *callback_args, **callback_kwargs)
  File "/Library/Python/2.7/site-packages/django/views/decorators/csrf.py", line 57, in wrapped_view
    return view_func(*args, **kwargs)
  File "/Users/Uijune/Documents/tyrant_server/controller/roomcontroller.py", line 85, in leave_room
    username = request.POST['username']
  File "/Library/Python/2.7/site-packages/django/utils/datastructures.py", line 301, in __getitem__
    raise MultiValueDictKeyError(repr(key))
MultiValueDictKeyError: "'username'"
Not Found: /
Internal Server Error: /message/post
Traceback (most recent call last):
  File "/Library/Python/2.7/site-packages/django/core/handlers/base.py", line 90, in get_response
    response = middleware_method(request)
  File "/Library/Python/2.7/site-packages/django/middleware/common.py", line 71, in process_request
    if (not urlresolvers.is_valid_path(request.path_info, urlconf) and
  File "/Library/Python/2.7/site-packages/django/core/urlresolvers.py", line 573, in is_valid_path
    resolve(path, urlconf)
  File "/Library/Python/2.7/site-packages/django/core/urlresolvers.py", line 453, in resolve
    return get_resolver(urlconf).resolve(path)
  File "/Library/Python/2.7/site-packages/django/core/urlresolvers.py", line 320, in resolve
    sub_match = pattern.resolve(new_path)
  File "/Library/Python/2.7/site-packages/django/core/urlresolvers.py", line 222, in resolve
    return ResolverMatch(self.callback, args, kwargs, self.name)
  File "/Library/Python/2.7/site-packages/django/core/urlresolvers.py", line 229, in callback
    self._callback = get_callable(self._callback_str)
  File "/Library/Python/2.7/site-packages/django/utils/functional.py", line 32, in wrapper
    result = func(*args)
  File "/Library/Python/2.7/site-packages/django/core/urlresolvers.py", line 96, in get_callable
    mod = import_module(mod_name)
  File "/Library/Python/2.7/site-packages/django/utils/importlib.py", line 40, in import_module
    __import__(name)
  File "/Users/Uijune/Documents/tyrant_server/controller/messagecontroller.py", line 37
    @csrf_exempt, post_required
                ^
SyntaxError: invalid syntax
Internal Server Error: /message/post
Traceback (most recent call last):
  File "/Library/Python/2.7/site-packages/django/core/handlers/base.py", line 114, in get_response
    response = wrapped_callback(request, *callback_args, **callback_kwargs)
  File "/Library/Python/2.7/site-packages/django/views/decorators/csrf.py", line 57, in wrapped_view
    return view_func(*args, **kwargs)
  File "/Users/Uijune/Documents/tyrant_server/controller/messagecontroller.py", line 53, in post
    contents = smart_unicode(request.POST['contents'], encoding='utf-8', strings_only=False, errors='strict')
  File "/Library/Python/2.7/site-packages/django/utils/datastructures.py", line 301, in __getitem__
    raise MultiValueDictKeyError(repr(key))
MultiValueDictKeyError: "'contents'"
Internal Server Error: /message/read
Traceback (most recent call last):
  File "/Library/Python/2.7/site-packages/django/core/handlers/base.py", line 90, in get_response
    response = middleware_method(request)
  File "/Library/Python/2.7/site-packages/django/middleware/common.py", line 71, in process_request
    if (not urlresolvers.is_valid_path(request.path_info, urlconf) and
  File "/Library/Python/2.7/site-packages/django/core/urlresolvers.py", line 573, in is_valid_path
    resolve(path, urlconf)
  File "/Library/Python/2.7/site-packages/django/core/urlresolvers.py", line 453, in resolve
    return get_resolver(urlconf).resolve(path)
  File "/Library/Python/2.7/site-packages/django/core/urlresolvers.py", line 320, in resolve
    sub_match = pattern.resolve(new_path)
  File "/Library/Python/2.7/site-packages/django/core/urlresolvers.py", line 222, in resolve
    return ResolverMatch(self.callback, args, kwargs, self.name)
  File "/Library/Python/2.7/site-packages/django/core/urlresolvers.py", line 229, in callback
    self._callback = get_callable(self._callback_str)
  File "/Library/Python/2.7/site-packages/django/utils/functional.py", line 32, in wrapper
    result = func(*args)
  File "/Library/Python/2.7/site-packages/django/core/urlresolvers.py", line 96, in get_callable
    mod = import_module(mod_name)
  File "/Library/Python/2.7/site-packages/django/utils/importlib.py", line 40, in import_module
    __import__(name)
  File "/Users/Uijune/Documents/tyrant_server/controller/messagecontroller.py", line 149
    notifications = RoomNotifications.objects.filter(user=user, processed=False, query).order_by('message__reg_date')
SyntaxError: non-keyword arg after keyword arg
Internal Server Error: /message/read
Traceback (most recent call last):
  File "/Library/Python/2.7/site-packages/django/core/handlers/base.py", line 90, in get_response
    response = middleware_method(request)
  File "/Library/Python/2.7/site-packages/django/middleware/common.py", line 71, in process_request
    if (not urlresolvers.is_valid_path(request.path_info, urlconf) and
  File "/Library/Python/2.7/site-packages/django/core/urlresolvers.py", line 573, in is_valid_path
    resolve(path, urlconf)
  File "/Library/Python/2.7/site-packages/django/core/urlresolvers.py", line 453, in resolve
    return get_resolver(urlconf).resolve(path)
  File "/Library/Python/2.7/site-packages/django/core/urlresolvers.py", line 320, in resolve
    sub_match = pattern.resolve(new_path)
  File "/Library/Python/2.7/site-packages/django/core/urlresolvers.py", line 222, in resolve
    return ResolverMatch(self.callback, args, kwargs, self.name)
  File "/Library/Python/2.7/site-packages/django/core/urlresolvers.py", line 229, in callback
    self._callback = get_callable(self._callback_str)
  File "/Library/Python/2.7/site-packages/django/utils/functional.py", line 32, in wrapper
    result = func(*args)
  File "/Library/Python/2.7/site-packages/django/core/urlresolvers.py", line 96, in get_callable
    mod = import_module(mod_name)
  File "/Library/Python/2.7/site-packages/django/utils/importlib.py", line 40, in import_module
    __import__(name)
  File "/Users/Uijune/Documents/tyrant_server/controller/messagecontroller.py", line 149
    notifications = RoomNotifications.objects.filter(user=user, processed=False, query).order_by('message__reg_date')
SyntaxError: non-keyword arg after keyword arg
Internal Server Error: /message/new
Traceback (most recent call last):
  File "/Library/Python/2.7/site-packages/django/core/handlers/base.py", line 90, in get_response
    response = middleware_method(request)
  File "/Library/Python/2.7/site-packages/django/middleware/common.py", line 71, in process_request
    if (not urlresolvers.is_valid_path(request.path_info, urlconf) and
  File "/Library/Python/2.7/site-packages/django/core/urlresolvers.py", line 573, in is_valid_path
    resolve(path, urlconf)
  File "/Library/Python/2.7/site-packages/django/core/urlresolvers.py", line 453, in resolve
    return get_resolver(urlconf).resolve(path)
  File "/Library/Python/2.7/site-packages/django/core/urlresolvers.py", line 320, in resolve
    sub_match = pattern.resolve(new_path)
  File "/Library/Python/2.7/site-packages/django/core/urlresolvers.py", line 222, in resolve
    return ResolverMatch(self.callback, args, kwargs, self.name)
  File "/Library/Python/2.7/site-packages/django/core/urlresolvers.py", line 229, in callback
    self._callback = get_callable(self._callback_str)
  File "/Library/Python/2.7/site-packages/django/utils/functional.py", line 32, in wrapper
    result = func(*args)
  File "/Library/Python/2.7/site-packages/django/core/urlresolvers.py", line 96, in get_callable
    mod = import_module(mod_name)
  File "/Library/Python/2.7/site-packages/django/utils/importlib.py", line 40, in import_module
    __import__(name)
  File "/Users/Uijune/Documents/tyrant_server/controller/messagecontroller.py", line 149
    notifications = RoomNotifications.objects.filter(user=user, processed=False, query).order_by('message__reg_date')
SyntaxError: non-keyword arg after keyword arg
Not Found: /message_new
Internal Server Error: /message/new
Traceback (most recent call last):
  File "/Library/Python/2.7/site-packages/django/core/handlers/base.py", line 201, in get_response
    response = middleware_method(request, response)
  File "/Library/Python/2.7/site-packages/django/middleware/clickjacking.py", line 30, in process_response
    if response.get('X-Frame-Options', None) is not None:
AttributeError: 'function' object has no attribute 'get'
Internal Server Error: /message/new
Traceback (most recent call last):
  File "/Library/Python/2.7/site-packages/django/core/handlers/base.py", line 201, in get_response
    response = middleware_method(request, response)
  File "/Library/Python/2.7/site-packages/django/middleware/clickjacking.py", line 30, in process_response
    if response.get('X-Frame-Options', None) is not None:
AttributeError: 'function' object has no attribute 'get'
Internal Server Error: /message/new
Traceback (most recent call last):
  File "/Library/Python/2.7/site-packages/django/core/handlers/base.py", line 201, in get_response
    response = middleware_method(request, response)
  File "/Library/Python/2.7/site-packages/django/middleware/clickjacking.py", line 30, in process_response
    if response.get('X-Frame-Options', None) is not None:
AttributeError: 'function' object has no attribute 'get'
Internal Server Error: /message/new
Traceback (most recent call last):
  File "/Library/Python/2.7/site-packages/django/core/handlers/base.py", line 201, in get_response
    response = middleware_method(request, response)
  File "/Library/Python/2.7/site-packages/django/middleware/clickjacking.py", line 30, in process_response
    if response.get('X-Frame-Options', None) is not None:
AttributeError: 'function' object has no attribute 'get'
Internal Server Error: /message/new
Traceback (most recent call last):
  File "/Library/Python/2.7/site-packages/django/core/handlers/base.py", line 201, in get_response
    response = middleware_method(request, response)
  File "/Library/Python/2.7/site-packages/django/middleware/clickjacking.py", line 30, in process_response
    if response.get('X-Frame-Options', None) is not None:
AttributeError: 'function' object has no attribute 'get'
Not Found: /
Internal Server Error: /rooms/leave
Traceback (most recent call last):
  File "/Library/Python/2.7/site-packages/django/core/handlers/base.py", line 90, in get_response
    response = middleware_method(request)
  File "/Library/Python/2.7/site-packages/django/middleware/common.py", line 71, in process_request
    if (not urlresolvers.is_valid_path(request.path_info, urlconf) and
  File "/Library/Python/2.7/site-packages/django/core/urlresolvers.py", line 573, in is_valid_path
    resolve(path, urlconf)
  File "/Library/Python/2.7/site-packages/django/core/urlresolvers.py", line 453, in resolve
    return get_resolver(urlconf).resolve(path)
  File "/Library/Python/2.7/site-packages/django/core/urlresolvers.py", line 320, in resolve
    sub_match = pattern.resolve(new_path)
  File "/Library/Python/2.7/site-packages/django/core/urlresolvers.py", line 222, in resolve
    return ResolverMatch(self.callback, args, kwargs, self.name)
  File "/Library/Python/2.7/site-packages/django/core/urlresolvers.py", line 229, in callback
    self._callback = get_callable(self._callback_str)
  File "/Library/Python/2.7/site-packages/django/utils/functional.py", line 32, in wrapper
    result = func(*args)
  File "/Library/Python/2.7/site-packages/django/core/urlresolvers.py", line 96, in get_callable
    mod = import_module(mod_name)
  File "/Library/Python/2.7/site-packages/django/utils/importlib.py", line 40, in import_module
    __import__(name)
  File "/Users/Uijune/Documents/tyrant_server/controller/roomcontroller.py", line 47
    friends = friends_id.split(",")
                                  ^
IndentationError: unindent does not match any outer indentation level
Internal Server Error: /rooms/create
Traceback (most recent call last):
  File "/Library/Python/2.7/site-packages/django/core/handlers/base.py", line 90, in get_response
    response = middleware_method(request)
  File "/Library/Python/2.7/site-packages/django/middleware/common.py", line 71, in process_request
    if (not urlresolvers.is_valid_path(request.path_info, urlconf) and
  File "/Library/Python/2.7/site-packages/django/core/urlresolvers.py", line 573, in is_valid_path
    resolve(path, urlconf)
  File "/Library/Python/2.7/site-packages/django/core/urlresolvers.py", line 453, in resolve
    return get_resolver(urlconf).resolve(path)
  File "/Library/Python/2.7/site-packages/django/core/urlresolvers.py", line 320, in resolve
    sub_match = pattern.resolve(new_path)
  File "/Library/Python/2.7/site-packages/django/core/urlresolvers.py", line 222, in resolve
    return ResolverMatch(self.callback, args, kwargs, self.name)
  File "/Library/Python/2.7/site-packages/django/core/urlresolvers.py", line 229, in callback
    self._callback = get_callable(self._callback_str)
  File "/Library/Python/2.7/site-packages/django/utils/functional.py", line 32, in wrapper
    result = func(*args)
  File "/Library/Python/2.7/site-packages/django/core/urlresolvers.py", line 96, in get_callable
    mod = import_module(mod_name)
  File "/Library/Python/2.7/site-packages/django/utils/importlib.py", line 40, in import_module
    __import__(name)
  File "/Users/Uijune/Documents/tyrant_server/controller/roomcontroller.py", line 47
    friends = friends_id.split(",")
                                  ^
IndentationError: unindent does not match any outer indentation level
Internal Server Error: /message/new
Traceback (most recent call last):
  File "/Library/Python/2.7/site-packages/django/core/handlers/base.py", line 114, in get_response
    response = wrapped_callback(request, *callback_args, **callback_kwargs)
  File "/Library/Python/2.7/site-packages/django/views/decorators/csrf.py", line 57, in wrapped_view
    return view_func(*args, **kwargs)
  File "/Users/Uijune/Documents/tyrant_server/controller/messagecontroller.py", line 134, in new
    username = request.POST['username']
  File "/Library/Python/2.7/site-packages/django/utils/datastructures.py", line 301, in __getitem__
    raise MultiValueDictKeyError(repr(key))
MultiValueDictKeyError: "'username'"
Internal Server Error: /message/new
Traceback (most recent call last):
  File "/Library/Python/2.7/site-packages/django/core/handlers/base.py", line 114, in get_response
    response = wrapped_callback(request, *callback_args, **callback_kwargs)
  File "/Library/Python/2.7/site-packages/django/views/decorators/csrf.py", line 57, in wrapped_view
    return view_func(*args, **kwargs)
  File "/Users/Uijune/Documents/tyrant_server/controller/messagecontroller.py", line 134, in new
    username = request.POST['username']
  File "/Library/Python/2.7/site-packages/django/utils/datastructures.py", line 301, in __getitem__
    raise MultiValueDictKeyError(repr(key))
MultiValueDictKeyError: "'username'"
Internal Server Error: /message/new
Traceback (most recent call last):
  File "/Library/Python/2.7/site-packages/django/core/handlers/base.py", line 201, in get_response
    response = middleware_method(request, response)
  File "/Library/Python/2.7/site-packages/django/middleware/clickjacking.py", line 30, in process_response
    if response.get('X-Frame-Options', None) is not None:
AttributeError: 'function' object has no attribute 'get'
Internal Server Error: /message/new
Traceback (most recent call last):
  File "/Library/Python/2.7/site-packages/django/core/handlers/base.py", line 201, in get_response
    response = middleware_method(request, response)
  File "/Library/Python/2.7/site-packages/django/middleware/clickjacking.py", line 30, in process_response
    if response.get('X-Frame-Options', None) is not None:
AttributeError: 'function' object has no attribute 'get'
Internal Server Error: /message/new
Traceback (most recent call last):
  File "/Library/Python/2.7/site-packages/django/core/handlers/base.py", line 201, in get_response
    response = middleware_method(request, response)
  File "/Library/Python/2.7/site-packages/django/middleware/clickjacking.py", line 30, in process_response
    if response.get('X-Frame-Options', None) is not None:
AttributeError: 'function' object has no attribute 'get'
Not Found: /
Not Found: /room/info
Internal Server Error: /rooms/info
Traceback (most recent call last):
  File "/Library/Python/2.7/site-packages/django/core/handlers/base.py", line 114, in get_response
    response = wrapped_callback(request, *callback_args, **callback_kwargs)
  File "/Library/Python/2.7/site-packages/django/views/decorators/csrf.py", line 57, in wrapped_view
    return view_func(*args, **kwargs)
  File "/Users/Uijune/Documents/tyrant_server/controller/roomcontroller.py", line 160, in info
    return print_json(result)
NameError: global name 'result' is not defined
Internal Server Error: /rooms/info
Traceback (most recent call last):
  File "/Library/Python/2.7/site-packages/django/core/handlers/base.py", line 90, in get_response
    response = middleware_method(request)
  File "/Library/Python/2.7/site-packages/django/middleware/common.py", line 71, in process_request
    if (not urlresolvers.is_valid_path(request.path_info, urlconf) and
  File "/Library/Python/2.7/site-packages/django/core/urlresolvers.py", line 573, in is_valid_path
    resolve(path, urlconf)
  File "/Library/Python/2.7/site-packages/django/core/urlresolvers.py", line 453, in resolve
    return get_resolver(urlconf).resolve(path)
  File "/Library/Python/2.7/site-packages/django/core/urlresolvers.py", line 320, in resolve
    sub_match = pattern.resolve(new_path)
  File "/Library/Python/2.7/site-packages/django/core/urlresolvers.py", line 222, in resolve
    return ResolverMatch(self.callback, args, kwargs, self.name)
  File "/Library/Python/2.7/site-packages/django/core/urlresolvers.py", line 229, in callback
    self._callback = get_callable(self._callback_str)
  File "/Library/Python/2.7/site-packages/django/utils/functional.py", line 32, in wrapper
    result = func(*args)
  File "/Library/Python/2.7/site-packages/django/core/urlresolvers.py", line 96, in get_callable
    mod = import_module(mod_name)
  File "/Library/Python/2.7/site-packages/django/utils/importlib.py", line 40, in import_module
    __import__(name)
  File "/Users/Uijune/Documents/tyrant_server/controller/roomcontroller.py", line 122
    results = dict()
   ^
IndentationError: unexpected indent
Not Found: /
Not Found: /favicon.ico
Not Found: /
Not Found: /
Not Found: /favicon.ico
Internal Server Error: /user/update
Traceback (most recent call last):
  File "/Library/Python/2.7/site-packages/django/core/handlers/base.py", line 90, in get_response
    response = middleware_method(request)
  File "/Library/Python/2.7/site-packages/django/middleware/common.py", line 71, in process_request
    if (not urlresolvers.is_valid_path(request.path_info, urlconf) and
  File "/Library/Python/2.7/site-packages/django/core/urlresolvers.py", line 573, in is_valid_path
    resolve(path, urlconf)
  File "/Library/Python/2.7/site-packages/django/core/urlresolvers.py", line 453, in resolve
    return get_resolver(urlconf).resolve(path)
  File "/Library/Python/2.7/site-packages/django/core/urlresolvers.py", line 320, in resolve
    sub_match = pattern.resolve(new_path)
  File "/Library/Python/2.7/site-packages/django/core/urlresolvers.py", line 222, in resolve
    return ResolverMatch(self.callback, args, kwargs, self.name)
  File "/Library/Python/2.7/site-packages/django/core/urlresolvers.py", line 229, in callback
    self._callback = get_callable(self._callback_str)
  File "/Library/Python/2.7/site-packages/django/utils/functional.py", line 32, in wrapper
    result = func(*args)
  File "/Library/Python/2.7/site-packages/django/core/urlresolvers.py", line 96, in get_callable
    mod = import_module(mod_name)
  File "/Library/Python/2.7/site-packages/django/utils/importlib.py", line 40, in import_module
    __import__(name)
  File "/Users/Uijune/Documents/tyrant_server/controller/usercontroller.py", line 16, in <module>
    from controller.utils import *
  File "/Users/Uijune/Documents/tyrant_server/controller/utils.py", line 89
    def token_required(function):
   ^
IndentationError: unexpected unindent
Internal Server Error: /user/update
Traceback (most recent call last):
  File "/Library/Python/2.7/site-packages/django/core/handlers/base.py", line 90, in get_response
    response = middleware_method(request)
  File "/Library/Python/2.7/site-packages/django/middleware/common.py", line 71, in process_request
    if (not urlresolvers.is_valid_path(request.path_info, urlconf) and
  File "/Library/Python/2.7/site-packages/django/core/urlresolvers.py", line 573, in is_valid_path
    resolve(path, urlconf)
  File "/Library/Python/2.7/site-packages/django/core/urlresolvers.py", line 453, in resolve
    return get_resolver(urlconf).resolve(path)
  File "/Library/Python/2.7/site-packages/django/core/urlresolvers.py", line 320, in resolve
    sub_match = pattern.resolve(new_path)
  File "/Library/Python/2.7/site-packages/django/core/urlresolvers.py", line 222, in resolve
    return ResolverMatch(self.callback, args, kwargs, self.name)
  File "/Library/Python/2.7/site-packages/django/core/urlresolvers.py", line 229, in callback
    self._callback = get_callable(self._callback_str)
  File "/Library/Python/2.7/site-packages/django/utils/functional.py", line 32, in wrapper
    result = func(*args)
  File "/Library/Python/2.7/site-packages/django/core/urlresolvers.py", line 96, in get_callable
    mod = import_module(mod_name)
  File "/Library/Python/2.7/site-packages/django/utils/importlib.py", line 40, in import_module
    __import__(name)
  File "/Users/Uijune/Documents/tyrant_server/controller/usercontroller.py", line 16, in <module>
    from controller.utils import *
  File "/Users/Uijune/Documents/tyrant_server/controller/utils.py", line 139
    retur False
              ^
SyntaxError: invalid syntax
Internal Server Error: /user/update
Traceback (most recent call last):
  File "/Library/Python/2.7/site-packages/django/core/handlers/base.py", line 90, in get_response
    response = middleware_method(request)
  File "/Library/Python/2.7/site-packages/django/middleware/common.py", line 71, in process_request
    if (not urlresolvers.is_valid_path(request.path_info, urlconf) and
  File "/Library/Python/2.7/site-packages/django/core/urlresolvers.py", line 573, in is_valid_path
    resolve(path, urlconf)
  File "/Library/Python/2.7/site-packages/django/core/urlresolvers.py", line 453, in resolve
    return get_resolver(urlconf).resolve(path)
  File "/Library/Python/2.7/site-packages/django/core/urlresolvers.py", line 320, in resolve
    sub_match = pattern.resolve(new_path)
  File "/Library/Python/2.7/site-packages/django/core/urlresolvers.py", line 222, in resolve
    return ResolverMatch(self.callback, args, kwargs, self.name)
  File "/Library/Python/2.7/site-packages/django/core/urlresolvers.py", line 229, in callback
    self._callback = get_callable(self._callback_str)
  File "/Library/Python/2.7/site-packages/django/utils/functional.py", line 32, in wrapper
    result = func(*args)
  File "/Library/Python/2.7/site-packages/django/core/urlresolvers.py", line 96, in get_callable
    mod = import_module(mod_name)
  File "/Library/Python/2.7/site-packages/django/utils/importlib.py", line 40, in import_module
    __import__(name)
  File "/Users/Uijune/Documents/tyrant_server/controller/usercontroller.py", line 16, in <module>
    from controller.utils import *
  File "/Users/Uijune/Documents/tyrant_server/controller/utils.py", line 139
    retur False
              ^
SyntaxError: invalid syntax
Internal Server Error: /user/update
Traceback (most recent call last):
  File "/Library/Python/2.7/site-packages/django/core/handlers/base.py", line 201, in get_response
    response = middleware_method(request, response)
  File "/Library/Python/2.7/site-packages/django/middleware/clickjacking.py", line 30, in process_response
    if response.get('X-Frame-Options', None) is not None:
AttributeError: 'AccessToken' object has no attribute 'get'
Internal Server Error: /user/update
Traceback (most recent call last):
  File "/Library/Python/2.7/site-packages/django/core/handlers/base.py", line 201, in get_response
    response = middleware_method(request, response)
  File "/Library/Python/2.7/site-packages/django/middleware/clickjacking.py", line 30, in process_response
    if response.get('X-Frame-Options', None) is not None:
AttributeError: 'AccessToken' object has no attribute 'get'
Internal Server Error: /user/update
Traceback (most recent call last):
  File "/Library/Python/2.7/site-packages/django/core/handlers/base.py", line 201, in get_response
    response = middleware_method(request, response)
  File "/Library/Python/2.7/site-packages/django/middleware/clickjacking.py", line 30, in process_response
    if response.get('X-Frame-Options', None) is not None:
AttributeError: 'AccessToken' object has no attribute 'get'
Internal Server Error: /user/update
Traceback (most recent call last):
  File "/Library/Python/2.7/site-packages/django/core/handlers/base.py", line 201, in get_response
    response = middleware_method(request, response)
  File "/Library/Python/2.7/site-packages/django/middleware/clickjacking.py", line 30, in process_response
    if response.get('X-Frame-Options', None) is not None:
AttributeError: 'AccessToken' object has no attribute 'get'
Internal Server Error: /user/update
Traceback (most recent call last):
  File "/Library/Python/2.7/site-packages/django/core/handlers/base.py", line 201, in get_response
    response = middleware_method(request, response)
  File "/Library/Python/2.7/site-packages/django/middleware/clickjacking.py", line 30, in process_response
    if response.get('X-Frame-Options', None) is not None:
  File "/Library/Python/2.7/site-packages/django/db/models/query.py", line 298, in get
    clone = self.filter(*args, **kwargs)
  File "/Library/Python/2.7/site-packages/django/db/models/query.py", line 590, in filter
    return self._filter_or_exclude(False, *args, **kwargs)
  File "/Library/Python/2.7/site-packages/django/db/models/query.py", line 608, in _filter_or_exclude
    clone.query.add_q(Q(*args, **kwargs))
  File "/Library/Python/2.7/site-packages/django/db/models/sql/query.py", line 1192, in add_q
    if not self.need_having(q_object):
  File "/Library/Python/2.7/site-packages/django/db/models/sql/query.py", line 1155, in need_having
    return any(self.need_having(c) for c in obj.children)
  File "/Library/Python/2.7/site-packages/django/db/models/sql/query.py", line 1155, in <genexpr>
    return any(self.need_having(c) for c in obj.children)
  File "/Library/Python/2.7/site-packages/django/db/models/sql/query.py", line 1152, in need_having
    return (refs_aggregate(obj[0].split(LOOKUP_SEP), self.aggregates)
TypeError: 'NoneType' object has no attribute '__getitem__'
Internal Server Error: /user/update
Traceback (most recent call last):
  File "/Library/Python/2.7/site-packages/django/core/handlers/base.py", line 201, in get_response
    response = middleware_method(request, response)
  File "/Library/Python/2.7/site-packages/django/middleware/clickjacking.py", line 30, in process_response
    if response.get('X-Frame-Options', None) is not None:
AttributeError: 'AccessToken' object has no attribute 'get'
Internal Server Error: /user/update
Traceback (most recent call last):
  File "/Library/Python/2.7/site-packages/django/core/handlers/base.py", line 201, in get_response
    response = middleware_method(request, response)
  File "/Library/Python/2.7/site-packages/django/middleware/clickjacking.py", line 30, in process_response
    if response.get('X-Frame-Options', None) is not None:
AttributeError: 'AccessToken' object has no attribute 'get'
Internal Server Error: /user/update
Traceback (most recent call last):
  File "/Library/Python/2.7/site-packages/django/core/handlers/base.py", line 201, in get_response
    response = middleware_method(request, response)
  File "/Library/Python/2.7/site-packages/django/middleware/clickjacking.py", line 30, in process_response
    if response.get('X-Frame-Options', None) is not None:
AttributeError: 'AccessToken' object has no attribute 'get'
Internal Server Error: /user/update
Traceback (most recent call last):
  File "/Library/Python/2.7/site-packages/django/core/handlers/base.py", line 201, in get_response
    response = middleware_method(request, response)
  File "/Library/Python/2.7/site-packages/django/middleware/clickjacking.py", line 30, in process_response
    if response.get('X-Frame-Options', None) is not None:
AttributeError: 'AccessToken' object has no attribute 'get'
Internal Server Error: /user/update
Traceback (most recent call last):
  File "/Library/Python/2.7/site-packages/django/core/handlers/base.py", line 201, in get_response
    response = middleware_method(request, response)
  File "/Library/Python/2.7/site-packages/django/middleware/clickjacking.py", line 30, in process_response
    if response.get('X-Frame-Options', None) is not None:
AttributeError: 'AccessToken' object has no attribute 'get'
Internal Server Error: /user/update
Traceback (most recent call last):
  File "/Library/Python/2.7/site-packages/django/core/handlers/base.py", line 201, in get_response
    response = middleware_method(request, response)
  File "/Library/Python/2.7/site-packages/django/middleware/clickjacking.py", line 30, in process_response
    if response.get('X-Frame-Options', None) is not None:
AttributeError: 'AccessToken' object has no attribute 'get'
Internal Server Error: /user/update
Traceback (most recent call last):
  File "/Library/Python/2.7/site-packages/django/core/handlers/base.py", line 201, in get_response
    response = middleware_method(request, response)
  File "/Library/Python/2.7/site-packages/django/middleware/clickjacking.py", line 30, in process_response
    if response.get('X-Frame-Options', None) is not None:
AttributeError: 'AccessToken' object has no attribute 'get'
Internal Server Error: /user/update
Traceback (most recent call last):
  File "/Library/Python/2.7/site-packages/django/core/handlers/base.py", line 201, in get_response
    response = middleware_method(request, response)
  File "/Library/Python/2.7/site-packages/django/middleware/clickjacking.py", line 30, in process_response
    if response.get('X-Frame-Options', None) is not None:
AttributeError: 'AccessToken' object has no attribute 'get'
Internal Server Error: /user/update
Traceback (most recent call last):
  File "/Library/Python/2.7/site-packages/django/core/handlers/base.py", line 201, in get_response
    response = middleware_method(request, response)
  File "/Library/Python/2.7/site-packages/django/middleware/clickjacking.py", line 30, in process_response
    if response.get('X-Frame-Options', None) is not None:
AttributeError: 'function' object has no attribute 'get'
Internal Server Error: /user/update
Traceback (most recent call last):
  File "/Library/Python/2.7/site-packages/django/core/handlers/base.py", line 201, in get_response
    response = middleware_method(request, response)
  File "/Library/Python/2.7/site-packages/django/middleware/clickjacking.py", line 30, in process_response
    if response.get('X-Frame-Options', None) is not None:
AttributeError: 'function' object has no attribute 'get'
Internal Server Error: /user/update
Traceback (most recent call last):
  File "/Library/Python/2.7/site-packages/django/core/handlers/base.py", line 201, in get_response
    response = middleware_method(request, response)
  File "/Library/Python/2.7/site-packages/django/middleware/clickjacking.py", line 30, in process_response
    if response.get('X-Frame-Options', None) is not None:
AttributeError: 'function' object has no attribute 'get'
Internal Server Error: /user/update
Traceback (most recent call last):
  File "/Library/Python/2.7/site-packages/django/core/handlers/base.py", line 201, in get_response
    response = middleware_method(request, response)
  File "/Library/Python/2.7/site-packages/django/middleware/clickjacking.py", line 30, in process_response
    if response.get('X-Frame-Options', None) is not None:
AttributeError: 'function' object has no attribute 'get'
Internal Server Error: /user/update
Traceback (most recent call last):
  File "/Library/Python/2.7/site-packages/django/core/handlers/base.py", line 201, in get_response
    response = middleware_method(request, response)
  File "/Library/Python/2.7/site-packages/django/middleware/clickjacking.py", line 30, in process_response
    if response.get('X-Frame-Options', None) is not None:
AttributeError: 'function' object has no attribute 'get'
Internal Server Error: /user/update
Traceback (most recent call last):
  File "/Library/Python/2.7/site-packages/django/core/handlers/base.py", line 201, in get_response
    response = middleware_method(request, response)
  File "/Library/Python/2.7/site-packages/django/middleware/clickjacking.py", line 30, in process_response
    if response.get('X-Frame-Options', None) is not None:
AttributeError: 'function' object has no attribute 'get'
Internal Server Error: /user/update
Traceback (most recent call last):
  File "/Library/Python/2.7/site-packages/django/core/handlers/base.py", line 201, in get_response
    response = middleware_method(request, response)
  File "/Library/Python/2.7/site-packages/django/middleware/clickjacking.py", line 30, in process_response
    if response.get('X-Frame-Options', None) is not None:
AttributeError: 'function' object has no attribute 'get'
Internal Server Error: /user/update
Traceback (most recent call last):
  File "/Library/Python/2.7/site-packages/django/core/handlers/base.py", line 201, in get_response
    response = middleware_method(request, response)
  File "/Library/Python/2.7/site-packages/django/middleware/clickjacking.py", line 30, in process_response
    if response.get('X-Frame-Options', None) is not None:
AttributeError: 'function' object has no attribute 'get'
Internal Server Error: /user/update
Traceback (most recent call last):
  File "/Library/Python/2.7/site-packages/django/core/handlers/base.py", line 201, in get_response
    response = middleware_method(request, response)
  File "/Library/Python/2.7/site-packages/django/middleware/clickjacking.py", line 30, in process_response
    if response.get('X-Frame-Options', None) is not None:
AttributeError: 'function' object has no attribute 'get'
Internal Server Error: /user/update
Traceback (most recent call last):
  File "/Library/Python/2.7/site-packages/django/core/handlers/base.py", line 201, in get_response
    response = middleware_method(request, response)
  File "/Library/Python/2.7/site-packages/django/middleware/clickjacking.py", line 30, in process_response
    if response.get('X-Frame-Options', None) is not None:
AttributeError: 'function' object has no attribute 'get'
Internal Server Error: /user/update
Traceback (most recent call last):
  File "/Library/Python/2.7/site-packages/django/core/handlers/base.py", line 201, in get_response
    response = middleware_method(request, response)
  File "/Library/Python/2.7/site-packages/django/middleware/clickjacking.py", line 30, in process_response
    if response.get('X-Frame-Options', None) is not None:
AttributeError: 'function' object has no attribute 'get'
Internal Server Error: /user/update
Traceback (most recent call last):
  File "/Library/Python/2.7/site-packages/django/core/handlers/base.py", line 201, in get_response
    response = middleware_method(request, response)
  File "/Library/Python/2.7/site-packages/django/middleware/clickjacking.py", line 30, in process_response
    if response.get('X-Frame-Options', None) is not None:
AttributeError: 'function' object has no attribute 'get'
Internal Server Error: /user/update
Traceback (most recent call last):
  File "/Library/Python/2.7/site-packages/django/core/handlers/base.py", line 201, in get_response
    response = middleware_method(request, response)
  File "/Library/Python/2.7/site-packages/django/middleware/clickjacking.py", line 30, in process_response
    if response.get('X-Frame-Options', None) is not None:
AttributeError: 'function' object has no attribute 'get'
Internal Server Error: /user/update
Traceback (most recent call last):
  File "/Library/Python/2.7/site-packages/django/core/handlers/base.py", line 201, in get_response
    response = middleware_method(request, response)
  File "/Library/Python/2.7/site-packages/django/middleware/clickjacking.py", line 30, in process_response
    if response.get('X-Frame-Options', None) is not None:
AttributeError: 'function' object has no attribute 'get'
Internal Server Error: /user/update
Traceback (most recent call last):
  File "/Library/Python/2.7/site-packages/django/core/handlers/base.py", line 201, in get_response
    response = middleware_method(request, response)
  File "/Library/Python/2.7/site-packages/django/middleware/clickjacking.py", line 30, in process_response
    if response.get('X-Frame-Options', None) is not None:
AttributeError: 'function' object has no attribute 'get'
Internal Server Error: /user/update
Traceback (most recent call last):
  File "/Library/Python/2.7/site-packages/django/core/handlers/base.py", line 201, in get_response
    response = middleware_method(request, response)
  File "/Library/Python/2.7/site-packages/django/middleware/clickjacking.py", line 30, in process_response
    if response.get('X-Frame-Options', None) is not None:
AttributeError: 'function' object has no attribute 'get'
Internal Server Error: /user/update
Traceback (most recent call last):
  File "/Library/Python/2.7/site-packages/django/core/handlers/base.py", line 114, in get_response
    response = wrapped_callback(request, *callback_args, **callback_kwargs)
  File "/Library/Python/2.7/site-packages/django/views/decorators/csrf.py", line 57, in wrapped_view
    return view_func(*args, **kwargs)
  File "/Users/Uijune/Documents/tyrant_server/controller/utils.py", line 130, in decorated
    return func(request, *args, **kwargs)
  File "/Users/Uijune/Documents/tyrant_server/controller/utils.py", line 99, in decorator
    return func(request, *args, **kwargs)
  File "/Users/Uijune/Documents/tyrant_server/controller/usercontroller.py", line 157, in update
    password = request.POST['password']
  File "/Library/Python/2.7/site-packages/django/utils/datastructures.py", line 301, in __getitem__
    raise MultiValueDictKeyError(repr(key))
MultiValueDictKeyError: "'password'"
Internal Server Error: /user/update
Traceback (most recent call last):
  File "/Library/Python/2.7/site-packages/django/core/handlers/base.py", line 114, in get_response
    response = wrapped_callback(request, *callback_args, **callback_kwargs)
  File "/Library/Python/2.7/site-packages/django/views/decorators/csrf.py", line 57, in wrapped_view
    return view_func(*args, **kwargs)
  File "/Users/Uijune/Documents/tyrant_server/controller/utils.py", line 130, in decorated
    return func(request, *args, **kwargs)
  File "/Users/Uijune/Documents/tyrant_server/controller/utils.py", line 99, in decorator
    return func(request, *args, **kwargs)
  File "/Users/Uijune/Documents/tyrant_server/controller/usercontroller.py", line 157, in update
    password = request.POST['password']
  File "/Library/Python/2.7/site-packages/django/utils/datastructures.py", line 301, in __getitem__
    raise MultiValueDictKeyError(repr(key))
MultiValueDictKeyError: "'password'"
Internal Server Error: /user/update
Traceback (most recent call last):
  File "/Library/Python/2.7/site-packages/django/core/handlers/base.py", line 114, in get_response
    response = wrapped_callback(request, *callback_args, **callback_kwargs)
  File "/Library/Python/2.7/site-packages/django/views/decorators/csrf.py", line 57, in wrapped_view
    return view_func(*args, **kwargs)
  File "/Users/Uijune/Documents/tyrant_server/controller/utils.py", line 130, in decorated
    return func(request, *args, **kwargs)
  File "/Users/Uijune/Documents/tyrant_server/controller/utils.py", line 99, in decorator
    return func(request, *args, **kwargs)
  File "/Users/Uijune/Documents/tyrant_server/controller/usercontroller.py", line 157, in update
    password = request.POST['password']
  File "/Library/Python/2.7/site-packages/django/utils/datastructures.py", line 301, in __getitem__
    raise MultiValueDictKeyError(repr(key))
MultiValueDictKeyError: "'password'"
Internal Server Error: /user/update
Traceback (most recent call last):
  File "/Library/Python/2.7/site-packages/django/core/handlers/base.py", line 114, in get_response
    response = wrapped_callback(request, *callback_args, **callback_kwargs)
  File "/Library/Python/2.7/site-packages/django/views/decorators/csrf.py", line 57, in wrapped_view
    return view_func(*args, **kwargs)
  File "/Users/Uijune/Documents/tyrant_server/controller/utils.py", line 131, in decorated
    return func(request, *args, **kwargs)
  File "/Users/Uijune/Documents/tyrant_server/controller/utils.py", line 100, in decorator
    return func(request, *args, **kwargs)
  File "/Users/Uijune/Documents/tyrant_server/controller/usercontroller.py", line 157, in update
    password = request.POST['password']
  File "/Library/Python/2.7/site-packages/django/utils/datastructures.py", line 301, in __getitem__
    raise MultiValueDictKeyError(repr(key))
MultiValueDictKeyError: "'password'"
Internal Server Error: /user/update
Traceback (most recent call last):
  File "/Library/Python/2.7/site-packages/django/core/handlers/base.py", line 90, in get_response
    response = middleware_method(request)
  File "/Library/Python/2.7/site-packages/django/middleware/common.py", line 71, in process_request
    if (not urlresolvers.is_valid_path(request.path_info, urlconf) and
  File "/Library/Python/2.7/site-packages/django/core/urlresolvers.py", line 573, in is_valid_path
    resolve(path, urlconf)
  File "/Library/Python/2.7/site-packages/django/core/urlresolvers.py", line 453, in resolve
    return get_resolver(urlconf).resolve(path)
  File "/Library/Python/2.7/site-packages/django/core/urlresolvers.py", line 320, in resolve
    sub_match = pattern.resolve(new_path)
  File "/Library/Python/2.7/site-packages/django/core/urlresolvers.py", line 222, in resolve
    return ResolverMatch(self.callback, args, kwargs, self.name)
  File "/Library/Python/2.7/site-packages/django/core/urlresolvers.py", line 229, in callback
    self._callback = get_callable(self._callback_str)
  File "/Library/Python/2.7/site-packages/django/utils/functional.py", line 32, in wrapper
    result = func(*args)
  File "/Library/Python/2.7/site-packages/django/core/urlresolvers.py", line 96, in get_callable
    mod = import_module(mod_name)
  File "/Library/Python/2.7/site-packages/django/utils/importlib.py", line 40, in import_module
    __import__(name)
  File "/Users/Uijune/Documents/tyrant_server/controller/usercontroller.py", line 153
    @post_required, token_required
                  ^
SyntaxError: invalid syntax
Internal Server Error: /user/update
Traceback (most recent call last):
  File "/Library/Python/2.7/site-packages/django/core/handlers/base.py", line 90, in get_response
    response = middleware_method(request)
  File "/Library/Python/2.7/site-packages/django/middleware/common.py", line 71, in process_request
    if (not urlresolvers.is_valid_path(request.path_info, urlconf) and
  File "/Library/Python/2.7/site-packages/django/core/urlresolvers.py", line 573, in is_valid_path
    resolve(path, urlconf)
  File "/Library/Python/2.7/site-packages/django/core/urlresolvers.py", line 453, in resolve
    return get_resolver(urlconf).resolve(path)
  File "/Library/Python/2.7/site-packages/django/core/urlresolvers.py", line 320, in resolve
    sub_match = pattern.resolve(new_path)
  File "/Library/Python/2.7/site-packages/django/core/urlresolvers.py", line 222, in resolve
    return ResolverMatch(self.callback, args, kwargs, self.name)
  File "/Library/Python/2.7/site-packages/django/core/urlresolvers.py", line 229, in callback
    self._callback = get_callable(self._callback_str)
  File "/Library/Python/2.7/site-packages/django/utils/functional.py", line 32, in wrapper
    result = func(*args)
  File "/Library/Python/2.7/site-packages/django/core/urlresolvers.py", line 96, in get_callable
    mod = import_module(mod_name)
  File "/Library/Python/2.7/site-packages/django/utils/importlib.py", line 40, in import_module
    __import__(name)
  File "/Users/Uijune/Documents/tyrant_server/controller/usercontroller.py", line 153
    @post_required, token_required
                  ^
SyntaxError: invalid syntax
Not Found: /
Not Found: /
Not Found: /add
Not Found: /
Not Found: /oauth2/access_otken
Not Found: /adsf
Not Found: /adsf
Not Found: /adsf
Not Found: /
Not Found: /apia
Not Found: /apia
Not Found: /
Not Found: /oauth2/1234
Not Found: /
Not Found: /
Not Found: /friends/list
Internal Server Error: /friends/list
Traceback (most recent call last):
  File "/Library/Python/2.7/site-packages/django/core/handlers/base.py", line 132, in get_response
    raise ValueError("The view %s.%s didn't return an HttpResponse object." % (callback.__module__, view_name))
ValueError: The view controller.utils.decorated didn't return an HttpResponse object.
Internal Server Error: /friends/list
Traceback (most recent call last):
  File "/Library/Python/2.7/site-packages/django/core/handlers/base.py", line 132, in get_response
    raise ValueError("The view %s.%s didn't return an HttpResponse object." % (callback.__module__, view_name))
ValueError: The view controller.utils.decorated didn't return an HttpResponse object.
Internal Server Error: /friends/list
Traceback (most recent call last):
  File "/Library/Python/2.7/site-packages/django/core/handlers/base.py", line 132, in get_response
    raise ValueError("The view %s.%s didn't return an HttpResponse object." % (callback.__module__, view_name))
ValueError: The view controller.utils.decorated didn't return an HttpResponse object.
Internal Server Error: /friends/list
Traceback (most recent call last):
  File "/Library/Python/2.7/site-packages/django/core/handlers/base.py", line 132, in get_response
    raise ValueError("The view %s.%s didn't return an HttpResponse object." % (callback.__module__, view_name))
ValueError: The view controller.utils.decorator didn't return an HttpResponse object.
Internal Server Error: /friends/list
Traceback (most recent call last):
  File "/Library/Python/2.7/site-packages/django/core/handlers/base.py", line 132, in get_response
    raise ValueError("The view %s.%s didn't return an HttpResponse object." % (callback.__module__, view_name))
ValueError: The view controller.utils.decorator didn't return an HttpResponse object.
Not Found: /
Not Found: /api/consoe
Not Found: /
Internal Server Error: /friends/add
Traceback (most recent call last):
  File "/Library/Python/2.7/site-packages/django/core/handlers/base.py", line 90, in get_response
    response = middleware_method(request)
  File "/Library/Python/2.7/site-packages/django/middleware/common.py", line 71, in process_request
    if (not urlresolvers.is_valid_path(request.path_info, urlconf) and
  File "/Library/Python/2.7/site-packages/django/core/urlresolvers.py", line 573, in is_valid_path
    resolve(path, urlconf)
  File "/Library/Python/2.7/site-packages/django/core/urlresolvers.py", line 453, in resolve
    return get_resolver(urlconf).resolve(path)
  File "/Library/Python/2.7/site-packages/django/core/urlresolvers.py", line 320, in resolve
    sub_match = pattern.resolve(new_path)
  File "/Library/Python/2.7/site-packages/django/core/urlresolvers.py", line 222, in resolve
    return ResolverMatch(self.callback, args, kwargs, self.name)
  File "/Library/Python/2.7/site-packages/django/core/urlresolvers.py", line 229, in callback
    self._callback = get_callable(self._callback_str)
  File "/Library/Python/2.7/site-packages/django/utils/functional.py", line 32, in wrapper
    result = func(*args)
  File "/Library/Python/2.7/site-packages/django/core/urlresolvers.py", line 96, in get_callable
    mod = import_module(mod_name)
  File "/Library/Python/2.7/site-packages/django/utils/importlib.py", line 40, in import_module
    __import__(name)
  File "/Users/Uijune/Documents/tyrant_server/controller/friendscontroller.py", line 59
    pirnt f_user
               ^
SyntaxError: invalid syntax
Not Found: /11api/console/add_friends
Internal Server Error: /message/post
Traceback (most recent call last):
  File "/Library/Python/2.7/site-packages/django/core/handlers/base.py", line 90, in get_response
    response = middleware_method(request)
  File "/Library/Python/2.7/site-packages/django/middleware/common.py", line 71, in process_request
    if (not urlresolvers.is_valid_path(request.path_info, urlconf) and
  File "/Library/Python/2.7/site-packages/django/core/urlresolvers.py", line 573, in is_valid_path
    resolve(path, urlconf)
  File "/Library/Python/2.7/site-packages/django/core/urlresolvers.py", line 453, in resolve
    return get_resolver(urlconf).resolve(path)
  File "/Library/Python/2.7/site-packages/django/core/urlresolvers.py", line 320, in resolve
    sub_match = pattern.resolve(new_path)
  File "/Library/Python/2.7/site-packages/django/core/urlresolvers.py", line 222, in resolve
    return ResolverMatch(self.callback, args, kwargs, self.name)
  File "/Library/Python/2.7/site-packages/django/core/urlresolvers.py", line 229, in callback
    self._callback = get_callable(self._callback_str)
  File "/Library/Python/2.7/site-packages/django/utils/functional.py", line 32, in wrapper
    result = func(*args)
  File "/Library/Python/2.7/site-packages/django/core/urlresolvers.py", line 96, in get_callable
    mod = import_module(mod_name)
  File "/Library/Python/2.7/site-packages/django/utils/importlib.py", line 40, in import_module
    __import__(name)
  File "/Users/Uijune/Documents/tyrant_server/controller/messagecontroller.py", line 41, in <module>
    @toekn_required
NameError: name 'toekn_required' is not defined
Not Found: /message/p1ost
Not Found: /
Internal Server Error: /message/post
Traceback (most recent call last):
  File "/Library/Python/2.7/site-packages/django/core/handlers/base.py", line 90, in get_response
    response = middleware_method(request)
  File "/Library/Python/2.7/site-packages/django/middleware/common.py", line 71, in process_request
    if (not urlresolvers.is_valid_path(request.path_info, urlconf) and
  File "/Library/Python/2.7/site-packages/django/core/urlresolvers.py", line 573, in is_valid_path
    resolve(path, urlconf)
  File "/Library/Python/2.7/site-packages/django/core/urlresolvers.py", line 453, in resolve
    return get_resolver(urlconf).resolve(path)
  File "/Library/Python/2.7/site-packages/django/core/urlresolvers.py", line 320, in resolve
    sub_match = pattern.resolve(new_path)
  File "/Library/Python/2.7/site-packages/django/core/urlresolvers.py", line 222, in resolve
    return ResolverMatch(self.callback, args, kwargs, self.name)
  File "/Library/Python/2.7/site-packages/django/core/urlresolvers.py", line 229, in callback
    self._callback = get_callable(self._callback_str)
  File "/Library/Python/2.7/site-packages/django/utils/functional.py", line 32, in wrapper
    result = func(*args)
  File "/Library/Python/2.7/site-packages/django/core/urlresolvers.py", line 96, in get_callable
    mod = import_module(mod_name)
  File "/Library/Python/2.7/site-packages/django/utils/importlib.py", line 40, in import_module
    __import__(name)
  File "/Users/Uijune/Documents/tyrant_server/controller/messagecontroller.py", line 125
    notifications = RoomNotifications.objects.filter(user=user, processed=False, message__room__id=room_id, message__reg_date).order_by('message__reg_date')
SyntaxError: non-keyword arg after keyword arg
Internal Server Error: /message/post
Traceback (most recent call last):
  File "/Library/Python/2.7/site-packages/django/core/handlers/base.py", line 90, in get_response
    response = middleware_method(request)
  File "/Library/Python/2.7/site-packages/django/middleware/common.py", line 71, in process_request
    if (not urlresolvers.is_valid_path(request.path_info, urlconf) and
  File "/Library/Python/2.7/site-packages/django/core/urlresolvers.py", line 573, in is_valid_path
    resolve(path, urlconf)
  File "/Library/Python/2.7/site-packages/django/core/urlresolvers.py", line 453, in resolve
    return get_resolver(urlconf).resolve(path)
  File "/Library/Python/2.7/site-packages/django/core/urlresolvers.py", line 320, in resolve
    sub_match = pattern.resolve(new_path)
  File "/Library/Python/2.7/site-packages/django/core/urlresolvers.py", line 222, in resolve
    return ResolverMatch(self.callback, args, kwargs, self.name)
  File "/Library/Python/2.7/site-packages/django/core/urlresolvers.py", line 229, in callback
    self._callback = get_callable(self._callback_str)
  File "/Library/Python/2.7/site-packages/django/utils/functional.py", line 32, in wrapper
    result = func(*args)
  File "/Library/Python/2.7/site-packages/django/core/urlresolvers.py", line 96, in get_callable
    mod = import_module(mod_name)
  File "/Library/Python/2.7/site-packages/django/utils/importlib.py", line 40, in import_module
    __import__(name)
  File "/Users/Uijune/Documents/tyrant_server/controller/messagecontroller.py", line 125
    notifications = RoomNotifications.objects.filter(user=user, processed=False, message__room__id=room_id, message__reg_date).order_by('message__reg_date')
SyntaxError: non-keyword arg after keyword arg
Internal Server Error: /message/new
Traceback (most recent call last):
  File "/Library/Python/2.7/site-packages/django/core/handlers/base.py", line 90, in get_response
    response = middleware_method(request)
  File "/Library/Python/2.7/site-packages/django/middleware/common.py", line 71, in process_request
    if (not urlresolvers.is_valid_path(request.path_info, urlconf) and
  File "/Library/Python/2.7/site-packages/django/core/urlresolvers.py", line 573, in is_valid_path
    resolve(path, urlconf)
  File "/Library/Python/2.7/site-packages/django/core/urlresolvers.py", line 453, in resolve
    return get_resolver(urlconf).resolve(path)
  File "/Library/Python/2.7/site-packages/django/core/urlresolvers.py", line 320, in resolve
    sub_match = pattern.resolve(new_path)
  File "/Library/Python/2.7/site-packages/django/core/urlresolvers.py", line 222, in resolve
    return ResolverMatch(self.callback, args, kwargs, self.name)
  File "/Library/Python/2.7/site-packages/django/core/urlresolvers.py", line 229, in callback
    self._callback = get_callable(self._callback_str)
  File "/Library/Python/2.7/site-packages/django/utils/functional.py", line 32, in wrapper
    result = func(*args)
  File "/Library/Python/2.7/site-packages/django/core/urlresolvers.py", line 96, in get_callable
    mod = import_module(mod_name)
  File "/Library/Python/2.7/site-packages/django/utils/importlib.py", line 40, in import_module
    __import__(name)
  File "/Users/Uijune/Documents/tyrant_server/controller/messagecontroller.py", line 125
    notifications = RoomNotifications.objects.filter(user=user, processed=False, message__room__id=room_id, message__reg_date).order_by('message__reg_date')
SyntaxError: non-keyword arg after keyword arg
Not Found: /
Not Found: /favicon.ico
Not Found: /
Not Found: /
Not Found: /
Not Found: /
Not Found: /favicon.ico
Not Found: /
Not Found: /favicon.ico
Not Found: /room/create_room
Not Found: /messages/read
Not Found: /messages/new
Not Found: /
Not Found: /favicon.ico
Not Found: /
Not Found: /
Not Found: /favicon.ico
Not Found: /
Not Found: /
Not Found: /
Not Found: /favicon.ico
Not Found: /
Not Found: /
Not Found: /device/check123
Internal Server Error: /admin/
Traceback (most recent call last):
  File "/Library/Python/2.7/site-packages/django/core/handlers/base.py", line 101, in get_response
    resolver_match = resolver.resolve(request.path_info)
  File "/Library/Python/2.7/site-packages/django/core/urlresolvers.py", line 318, in resolve
    for pattern in self.url_patterns:
  File "/Library/Python/2.7/site-packages/django/core/urlresolvers.py", line 346, in url_patterns
    patterns = getattr(self.urlconf_module, "urlpatterns", self.urlconf_module)
  File "/Library/Python/2.7/site-packages/django/core/urlresolvers.py", line 341, in urlconf_module
    self._urlconf_module = import_module(self.urlconf_name)
  File "/Library/Python/2.7/site-packages/django/utils/importlib.py", line 40, in import_module
    __import__(name)
  File "/Users/Uijune/Documents/tyrant_server/tyrant_server/urls.py", line 63, in <module>
    ) + static(settings.MEDIA_URL, document_root=settings.MEDIA_ROOT) + static(settings.STATIC_URL, document_root=settings.STATIC_ROOT)
NameError: name 'csrf_exempt' is not defined
Internal Server Error: /access_token
Traceback (most recent call last):
  File "/Library/Python/2.7/site-packages/django/core/handlers/base.py", line 90, in get_response
    response = middleware_method(request)
  File "/Library/Python/2.7/site-packages/django/middleware/common.py", line 71, in process_request
    if (not urlresolvers.is_valid_path(request.path_info, urlconf) and
  File "/Library/Python/2.7/site-packages/django/core/urlresolvers.py", line 573, in is_valid_path
    resolve(path, urlconf)
  File "/Library/Python/2.7/site-packages/django/core/urlresolvers.py", line 453, in resolve
    return get_resolver(urlconf).resolve(path)
  File "/Library/Python/2.7/site-packages/django/core/urlresolvers.py", line 318, in resolve
    for pattern in self.url_patterns:
  File "/Library/Python/2.7/site-packages/django/core/urlresolvers.py", line 346, in url_patterns
    patterns = getattr(self.urlconf_module, "urlpatterns", self.urlconf_module)
  File "/Library/Python/2.7/site-packages/django/core/urlresolvers.py", line 341, in urlconf_module
    self._urlconf_module = import_module(self.urlconf_name)
  File "/Library/Python/2.7/site-packages/django/utils/importlib.py", line 40, in import_module
    __import__(name)
  File "/Users/Uijune/Documents/tyrant_server/tyrant_server/urls.py", line 63, in <module>
    ) + static(settings.MEDIA_URL, document_root=settings.MEDIA_ROOT) + static(settings.STATIC_URL, document_root=settings.STATIC_ROOT)
NameError: name 'csrf_exempt' is not defined
Internal Server Error: /access_token
Traceback (most recent call last):
  File "/Library/Python/2.7/site-packages/django/core/handlers/base.py", line 90, in get_response
    response = middleware_method(request)
  File "/Library/Python/2.7/site-packages/django/middleware/common.py", line 71, in process_request
    if (not urlresolvers.is_valid_path(request.path_info, urlconf) and
  File "/Library/Python/2.7/site-packages/django/core/urlresolvers.py", line 573, in is_valid_path
    resolve(path, urlconf)
  File "/Library/Python/2.7/site-packages/django/core/urlresolvers.py", line 453, in resolve
    return get_resolver(urlconf).resolve(path)
  File "/Library/Python/2.7/site-packages/django/core/urlresolvers.py", line 318, in resolve
    for pattern in self.url_patterns:
  File "/Library/Python/2.7/site-packages/django/core/urlresolvers.py", line 346, in url_patterns
    patterns = getattr(self.urlconf_module, "urlpatterns", self.urlconf_module)
  File "/Library/Python/2.7/site-packages/django/core/urlresolvers.py", line 341, in urlconf_module
    self._urlconf_module = import_module(self.urlconf_name)
  File "/Library/Python/2.7/site-packages/django/utils/importlib.py", line 40, in import_module
    __import__(name)
  File "/Users/Uijune/Documents/tyrant_server/tyrant_server/urls.py", line 63, in <module>
    ) + static(settings.MEDIA_URL, document_root=settings.MEDIA_ROOT) + static(settings.STATIC_URL, document_root=settings.STATIC_ROOT)
NameError: name 'controller' is not defined
Internal Server Error: /access_token
Traceback (most recent call last):
  File "/Library/Python/2.7/site-packages/django/core/handlers/base.py", line 90, in get_response
    response = middleware_method(request)
  File "/Library/Python/2.7/site-packages/django/middleware/common.py", line 71, in process_request
    if (not urlresolvers.is_valid_path(request.path_info, urlconf) and
  File "/Library/Python/2.7/site-packages/django/core/urlresolvers.py", line 573, in is_valid_path
    resolve(path, urlconf)
  File "/Library/Python/2.7/site-packages/django/core/urlresolvers.py", line 453, in resolve
    return get_resolver(urlconf).resolve(path)
  File "/Library/Python/2.7/site-packages/django/core/urlresolvers.py", line 320, in resolve
    sub_match = pattern.resolve(new_path)
  File "/Library/Python/2.7/site-packages/django/core/urlresolvers.py", line 222, in resolve
    return ResolverMatch(self.callback, args, kwargs, self.name)
  File "/Library/Python/2.7/site-packages/django/core/urlresolvers.py", line 229, in callback
    self._callback = get_callable(self._callback_str)
  File "/Library/Python/2.7/site-packages/django/utils/functional.py", line 32, in wrapper
    result = func(*args)
  File "/Library/Python/2.7/site-packages/django/core/urlresolvers.py", line 100, in get_callable
    not module_has_submodule(import_module(parentmod), submod)):
  File "/Library/Python/2.7/site-packages/django/utils/importlib.py", line 40, in import_module
    __import__(name)
ImportError: No module named AccessTokenView
Internal Server Error: /access_token
Traceback (most recent call last):
  File "/Library/Python/2.7/site-packages/django/core/handlers/base.py", line 90, in get_response
    response = middleware_method(request)
  File "/Library/Python/2.7/site-packages/django/middleware/common.py", line 71, in process_request
    if (not urlresolvers.is_valid_path(request.path_info, urlconf) and
  File "/Library/Python/2.7/site-packages/django/core/urlresolvers.py", line 573, in is_valid_path
    resolve(path, urlconf)
  File "/Library/Python/2.7/site-packages/django/core/urlresolvers.py", line 453, in resolve
    return get_resolver(urlconf).resolve(path)
  File "/Library/Python/2.7/site-packages/django/core/urlresolvers.py", line 320, in resolve
    sub_match = pattern.resolve(new_path)
  File "/Library/Python/2.7/site-packages/django/core/urlresolvers.py", line 222, in resolve
    return ResolverMatch(self.callback, args, kwargs, self.name)
  File "/Library/Python/2.7/site-packages/django/core/urlresolvers.py", line 229, in callback
    self._callback = get_callable(self._callback_str)
  File "/Library/Python/2.7/site-packages/django/utils/functional.py", line 32, in wrapper
    result = func(*args)
  File "/Library/Python/2.7/site-packages/django/core/urlresolvers.py", line 103, in get_callable
    (lookup_view, mod_name))
ViewDoesNotExist: Could not import controller.TyrantAccessTokenView.TAccessTokenView.as_view(). Parent module controller.TyrantAccessTokenView.TAccessTokenView does not exist.
Internal Server Error: /access_token
Traceback (most recent call last):
  File "/Library/Python/2.7/site-packages/django/core/handlers/base.py", line 90, in get_response
    response = middleware_method(request)
  File "/Library/Python/2.7/site-packages/django/middleware/common.py", line 71, in process_request
    if (not urlresolvers.is_valid_path(request.path_info, urlconf) and
  File "/Library/Python/2.7/site-packages/django/core/urlresolvers.py", line 573, in is_valid_path
    resolve(path, urlconf)
  File "/Library/Python/2.7/site-packages/django/core/urlresolvers.py", line 453, in resolve
    return get_resolver(urlconf).resolve(path)
  File "/Library/Python/2.7/site-packages/django/core/urlresolvers.py", line 320, in resolve
    sub_match = pattern.resolve(new_path)
  File "/Library/Python/2.7/site-packages/django/core/urlresolvers.py", line 222, in resolve
    return ResolverMatch(self.callback, args, kwargs, self.name)
  File "/Library/Python/2.7/site-packages/django/core/urlresolvers.py", line 229, in callback
    self._callback = get_callable(self._callback_str)
  File "/Library/Python/2.7/site-packages/django/utils/functional.py", line 32, in wrapper
    result = func(*args)
  File "/Library/Python/2.7/site-packages/django/core/urlresolvers.py", line 96, in get_callable
    mod = import_module(mod_name)
  File "/Library/Python/2.7/site-packages/django/utils/importlib.py", line 40, in import_module
    __import__(name)
  File "/Users/Uijune/Documents/tyrant_server/controller/TyrantAccessTokenView.py", line 9
    
   ^
IndentationError: expected an indented block
Internal Server Error: /access_token
Traceback (most recent call last):
  File "/Library/Python/2.7/site-packages/django/core/handlers/base.py", line 114, in get_response
    response = wrapped_callback(request, *callback_args, **callback_kwargs)
TypeError: __init__() takes exactly 1 argument (2 given)
Internal Server Error: /access_token
Traceback (most recent call last):
  File "/Library/Python/2.7/site-packages/django/core/handlers/base.py", line 90, in get_response
    response = middleware_method(request)
  File "/Library/Python/2.7/site-packages/django/middleware/common.py", line 71, in process_request
    if (not urlresolvers.is_valid_path(request.path_info, urlconf) and
  File "/Library/Python/2.7/site-packages/django/core/urlresolvers.py", line 573, in is_valid_path
    resolve(path, urlconf)
  File "/Library/Python/2.7/site-packages/django/core/urlresolvers.py", line 453, in resolve
    return get_resolver(urlconf).resolve(path)
  File "/Library/Python/2.7/site-packages/django/core/urlresolvers.py", line 320, in resolve
    sub_match = pattern.resolve(new_path)
  File "/Library/Python/2.7/site-packages/django/core/urlresolvers.py", line 222, in resolve
    return ResolverMatch(self.callback, args, kwargs, self.name)
  File "/Library/Python/2.7/site-packages/django/core/urlresolvers.py", line 229, in callback
    self._callback = get_callable(self._callback_str)
  File "/Library/Python/2.7/site-packages/django/utils/functional.py", line 32, in wrapper
    result = func(*args)
  File "/Library/Python/2.7/site-packages/django/core/urlresolvers.py", line 103, in get_callable
    (lookup_view, mod_name))
ViewDoesNotExist: Could not import controller.TyrantAccessTokenView.TAccessTokenView.as_view(). Parent module controller.TyrantAccessTokenView.TAccessTokenView does not exist.
Internal Server Error: /access_token
Traceback (most recent call last):
  File "/Library/Python/2.7/site-packages/django/core/handlers/base.py", line 90, in get_response
    response = middleware_method(request)
  File "/Library/Python/2.7/site-packages/django/middleware/common.py", line 71, in process_request
    if (not urlresolvers.is_valid_path(request.path_info, urlconf) and
  File "/Library/Python/2.7/site-packages/django/core/urlresolvers.py", line 573, in is_valid_path
    resolve(path, urlconf)
  File "/Library/Python/2.7/site-packages/django/core/urlresolvers.py", line 453, in resolve
    return get_resolver(urlconf).resolve(path)
  File "/Library/Python/2.7/site-packages/django/core/urlresolvers.py", line 318, in resolve
    for pattern in self.url_patterns:
  File "/Library/Python/2.7/site-packages/django/core/urlresolvers.py", line 346, in url_patterns
    patterns = getattr(self.urlconf_module, "urlpatterns", self.urlconf_module)
  File "/Library/Python/2.7/site-packages/django/core/urlresolvers.py", line 341, in urlconf_module
    self._urlconf_module = import_module(self.urlconf_name)
  File "/Library/Python/2.7/site-packages/django/utils/importlib.py", line 40, in import_module
    __import__(name)
  File "/Users/Uijune/Documents/tyrant_server/tyrant_server/urls.py", line 65, in <module>
    ) + static(settings.MEDIA_URL, document_root=settings.MEDIA_ROOT) + static(settings.STATIC_URL, document_root=settings.STATIC_ROOT)
NameError: name 'TyrantAccessTokenView' is not defined
Internal Server Error: /access_token
Traceback (most recent call last):
  File "/Library/Python/2.7/site-packages/django/core/handlers/base.py", line 90, in get_response
    response = middleware_method(request)
  File "/Library/Python/2.7/site-packages/django/middleware/common.py", line 71, in process_request
    if (not urlresolvers.is_valid_path(request.path_info, urlconf) and
  File "/Library/Python/2.7/site-packages/django/core/urlresolvers.py", line 573, in is_valid_path
    resolve(path, urlconf)
  File "/Library/Python/2.7/site-packages/django/core/urlresolvers.py", line 453, in resolve
    return get_resolver(urlconf).resolve(path)
  File "/Library/Python/2.7/site-packages/django/core/urlresolvers.py", line 318, in resolve
    for pattern in self.url_patterns:
  File "/Library/Python/2.7/site-packages/django/core/urlresolvers.py", line 346, in url_patterns
    patterns = getattr(self.urlconf_module, "urlpatterns", self.urlconf_module)
  File "/Library/Python/2.7/site-packages/django/core/urlresolvers.py", line 341, in urlconf_module
    self._urlconf_module = import_module(self.urlconf_name)
  File "/Library/Python/2.7/site-packages/django/utils/importlib.py", line 40, in import_module
    __import__(name)
  File "/Users/Uijune/Documents/tyrant_server/tyrant_server/urls.py", line 65, in <module>
    ) + static(settings.MEDIA_URL, document_root=settings.MEDIA_ROOT) + static(settings.STATIC_URL, document_root=settings.STATIC_ROOT)
AttributeError: 'module' object has no attribute 'TyrantAccessTokenView'
Internal Server Error: /access_token
Traceback (most recent call last):
  File "/Library/Python/2.7/site-packages/django/core/handlers/base.py", line 90, in get_response
    response = middleware_method(request)
  File "/Library/Python/2.7/site-packages/django/middleware/common.py", line 71, in process_request
    if (not urlresolvers.is_valid_path(request.path_info, urlconf) and
  File "/Library/Python/2.7/site-packages/django/core/urlresolvers.py", line 573, in is_valid_path
    resolve(path, urlconf)
  File "/Library/Python/2.7/site-packages/django/core/urlresolvers.py", line 453, in resolve
    return get_resolver(urlconf).resolve(path)
  File "/Library/Python/2.7/site-packages/django/core/urlresolvers.py", line 318, in resolve
    for pattern in self.url_patterns:
  File "/Library/Python/2.7/site-packages/django/core/urlresolvers.py", line 346, in url_patterns
    patterns = getattr(self.urlconf_module, "urlpatterns", self.urlconf_module)
  File "/Library/Python/2.7/site-packages/django/core/urlresolvers.py", line 341, in urlconf_module
    self._urlconf_module = import_module(self.urlconf_name)
  File "/Library/Python/2.7/site-packages/django/utils/importlib.py", line 40, in import_module
    __import__(name)
  File "/Users/Uijune/Documents/tyrant_server/tyrant_server/urls.py", line 65, in <module>
    ) + static(settings.MEDIA_URL, document_root=settings.MEDIA_ROOT) + static(settings.STATIC_URL, document_root=settings.STATIC_ROOT)
AttributeError: 'module' object has no attribute 'TyrantAccessTokenView'
Internal Server Error: /access_token
Traceback (most recent call last):
  File "/Library/Python/2.7/site-packages/django/core/handlers/base.py", line 90, in get_response
    response = middleware_method(request)
  File "/Library/Python/2.7/site-packages/django/middleware/common.py", line 71, in process_request
    if (not urlresolvers.is_valid_path(request.path_info, urlconf) and
  File "/Library/Python/2.7/site-packages/django/core/urlresolvers.py", line 573, in is_valid_path
    resolve(path, urlconf)
  File "/Library/Python/2.7/site-packages/django/core/urlresolvers.py", line 453, in resolve
    return get_resolver(urlconf).resolve(path)
  File "/Library/Python/2.7/site-packages/django/core/urlresolvers.py", line 318, in resolve
    for pattern in self.url_patterns:
  File "/Library/Python/2.7/site-packages/django/core/urlresolvers.py", line 346, in url_patterns
    patterns = getattr(self.urlconf_module, "urlpatterns", self.urlconf_module)
  File "/Library/Python/2.7/site-packages/django/core/urlresolvers.py", line 341, in urlconf_module
    self._urlconf_module = import_module(self.urlconf_name)
  File "/Library/Python/2.7/site-packages/django/utils/importlib.py", line 40, in import_module
    __import__(name)
  File "/Users/Uijune/Documents/tyrant_server/tyrant_server/urls.py", line 65, in <module>
    ) + static(settings.MEDIA_URL, document_root=settings.MEDIA_ROOT) + static(settings.STATIC_URL, document_root=settings.STATIC_ROOT)
AttributeError: 'module' object has no attribute 'TyrantAccessTokenView'
Forbidden (CSRF token missing or incorrect.): /access_token
Internal Server Error: /access_token
Traceback (most recent call last):
  File "/Library/Python/2.7/site-packages/django/core/handlers/base.py", line 90, in get_response
    response = middleware_method(request)
  File "/Library/Python/2.7/site-packages/django/middleware/common.py", line 71, in process_request
    if (not urlresolvers.is_valid_path(request.path_info, urlconf) and
  File "/Library/Python/2.7/site-packages/django/core/urlresolvers.py", line 573, in is_valid_path
    resolve(path, urlconf)
  File "/Library/Python/2.7/site-packages/django/core/urlresolvers.py", line 453, in resolve
    return get_resolver(urlconf).resolve(path)
  File "/Library/Python/2.7/site-packages/django/core/urlresolvers.py", line 318, in resolve
    for pattern in self.url_patterns:
  File "/Library/Python/2.7/site-packages/django/core/urlresolvers.py", line 346, in url_patterns
    patterns = getattr(self.urlconf_module, "urlpatterns", self.urlconf_module)
  File "/Library/Python/2.7/site-packages/django/core/urlresolvers.py", line 341, in urlconf_module
    self._urlconf_module = import_module(self.urlconf_name)
  File "/Library/Python/2.7/site-packages/django/utils/importlib.py", line 40, in import_module
    __import__(name)
  File "/Users/Uijune/Documents/tyrant_server/tyrant_server/urls.py", line 9, in <module>
    from controller.TyrantAccessTokenView import *
  File "/Users/Uijune/Documents/tyrant_server/controller/TyrantAccessTokenView.py", line 9
    
   ^
IndentationError: expected an indented block
Internal Server Error: /access_token
Traceback (most recent call last):
  File "/Library/Python/2.7/site-packages/django/core/handlers/base.py", line 90, in get_response
    response = middleware_method(request)
  File "/Library/Python/2.7/site-packages/django/middleware/common.py", line 71, in process_request
    if (not urlresolvers.is_valid_path(request.path_info, urlconf) and
  File "/Library/Python/2.7/site-packages/django/core/urlresolvers.py", line 573, in is_valid_path
    resolve(path, urlconf)
  File "/Library/Python/2.7/site-packages/django/core/urlresolvers.py", line 453, in resolve
    return get_resolver(urlconf).resolve(path)
  File "/Library/Python/2.7/site-packages/django/core/urlresolvers.py", line 318, in resolve
    for pattern in self.url_patterns:
  File "/Library/Python/2.7/site-packages/django/core/urlresolvers.py", line 346, in url_patterns
    patterns = getattr(self.urlconf_module, "urlpatterns", self.urlconf_module)
  File "/Library/Python/2.7/site-packages/django/core/urlresolvers.py", line 341, in urlconf_module
    self._urlconf_module = import_module(self.urlconf_name)
  File "/Library/Python/2.7/site-packages/django/utils/importlib.py", line 40, in import_module
    __import__(name)
  File "/Users/Uijune/Documents/tyrant_server/tyrant_server/urls.py", line 9, in <module>
    from controller.TyrantAccessTokenView import *
  File "/Users/Uijune/Documents/tyrant_server/controller/TyrantAccessTokenView.py", line 30
    pass
       ^
IndentationError: unindent does not match any outer indentation level
Not Found: /user/signUp
